Workbook

Sheet TEND_CANAIS
A1: REGIONAL | B1: DAT_MOVIMENTO | C1: DAT_MÊS | D1: ANO | E1: CANAL_PLAN | F1: DSC_INDICADOR | G1: COD_PLATAFORMA | H1: QTDE | I1: DESAFIO_QTD | J1: DAT_MOVIMENTO2 | K1: dat_tratada | L1: dia_semana | M1: TEND_QTD
A2: RSI | B2: 46054 | C2: =TEXT(B2,"MM") -> 02 | D2: =YEAR(B2) -> 2026 | E2: Hospitality PME | F2: Instalação | G2: FIXA | H2: 0 | I2: 0 | J2: =B2 -> 46054 | K2: =TEXT(J2,"MMM/AA") -> fev/26 | L2: =TEXT(J2,"DDD") -> dom | M2: =SUMIFS(BASE_FIXA_TEND!AN:AN,BASE_FIXA_TEND!$A:$A,$A2,BASE_FIXA_TEND!$B:$B,$E2,BASE_FIXA_TEND!$D:$D,$F2) -> 4
A3: RRE | B3: 46054 | C3: =TEXT(B3,"MM") -> 02 | D3: =YEAR(B3) -> 2026 | E3: Hospitality PME | F3: Instalação | G3: FIXA | H3: 0 | I3: 0 | J3: =B3 -> 46054 | K3: =TEXT(J3,"MMM/AA") -> fev/26 | L3: =TEXT(J3,"DDD") -> dom | M3: =SUMIFS(BASE_FIXA_TEND!AN:AN,BASE_FIXA_TEND!$A:$A,$A3,BASE_FIXA_TEND!$B:$B,$E3,BASE_FIXA_TEND!$D:$D,$F3) -> 0
A4: RMG | B4: 46054 | C4: =TEXT(B4,"MM") -> 02 | D4: =YEAR(B4) -> 2026 | E4: Hospitality PME | F4: Instalação | G4: FIXA | H4: 0 | I4: 0 | J4: =B4 -> 46054 | K4: =TEXT(J4,"MMM/AA") -> fev/26 | L4: =TEXT(J4,"DDD") -> dom | M4: =SUMIFS(BASE_FIXA_TEND!AN:AN,BASE_FIXA_TEND!$A:$A,$A4,BASE_FIXA_TEND!$B:$B,$E4,BASE_FIXA_TEND!$D:$D,$F4) -> 0
A5: RPS | B5: 46054 | C5: =TEXT(B5,"MM") -> 02 | D5: =YEAR(B5) -> 2026 | E5: Hospitality PME | F5: Instalação | G5: FIXA | H5: 0 | I5: 0 | J5: =B5 -> 46054 | K5: =TEXT(J5,"MMM/AA") -> fev/26 | L5: =TEXT(J5,"DDD") -> dom | M5: =SUMIFS(BASE_FIXA_TEND!AN:AN,BASE_FIXA_TEND!$A:$A,$A5,BASE_FIXA_TEND!$B:$B,$E5,BASE_FIXA_TEND!$D:$D,$F5) -> 0
A6: RRS | B6: 46054 | C6: =TEXT(B6,"MM") -> 02 | D6: =YEAR(B6) -> 2026 | E6: Hospitality PME | F6: Instalação | G6: FIXA | H6: 0 | I6: 0 | J6: =B6 -> 46054 | K6: =TEXT(J6,"MMM/AA") -> fev/26 | L6: =TEXT(J6,"DDD") -> dom | M6: =SUMIFS(BASE_FIXA_TEND!AN:AN,BASE_FIXA_TEND!$A:$A,$A6,BASE_FIXA_TEND!$B:$B,$E6,BASE_FIXA_TEND!$D:$D,$F6) -> 0
A7: RCO | B7: 46054 | C7: =TEXT(B7,"MM") -> 02 | D7: =YEAR(B7) -> 2026 | E7: Hospitality PME | F7: Instalação | G7: FIXA | H7: 0 | I7: 0 | J7: =B7 -> 46054 | K7: =TEXT(J7,"MMM/AA") -> fev/26 | L7: =TEXT(J7,"DDD") -> dom | M7: =SUMIFS(BASE_FIXA_TEND!AN:AN,BASE_FIXA_TEND!$A:$A,$A7,BASE_FIXA_TEND!$B:$B,$E7,BASE_FIXA_TEND!$D:$D,$F7) -> 0
A8: RNE | B8: 46054 | C8: =TEXT(B8,"MM") -> 02 | D8: =YEAR(B8) -> 2026 | E8: Hospitality PME | F8: Instalação | G8: FIXA | H8: 0 | I8: 0 | J8: =B8 -> 46054 | K8: =TEXT(J8,"MMM/AA") -> fev/26 | L8: =TEXT(J8,"DDD") -> dom | M8: =SUMIFS(BASE_FIXA_TEND!AN:AN,BASE_FIXA_TEND!$A:$A,$A8,BASE_FIXA_TEND!$B:$B,$E8,BASE_FIXA_TEND!$D:$D,$F8) -> 0
A9: RSC | B9: 46054 | C9: =TEXT(B9,"MM") -> 02 | D9: =YEAR(B9) -> 2026 | E9: Hospitality PME | F9: Instalação | G9: FIXA | H9: 0 | I9: 0 | J9: =B9 -> 46054 | K9: =TEXT(J9,"MMM/AA") -> fev/26 | L9: =TEXT(J9,"DDD") -> dom | M9: =SUMIFS(BASE_FIXA_TEND!AN:AN,BASE_FIXA_TEND!$A:$A,$A9,BASE_FIXA_TEND!$B:$B,$E9,BASE_FIXA_TEND!$D:$D,$F9) -> 30.718674
A10: RNO | B10: 46054 | C10: =TEXT(B10,"MM") -> 02 | D10: =YEAR(B10) -> 2026 | E10: Hospitality PME | F10: Instalação | G10: FIXA | H10: 0 | I10: 0 | J10: =B10 -> 46054 | K10: =TEXT(J10,"MMM/AA") -> fev/26 | L10: =TEXT(J10,"DDD") -> dom | M10: =SUMIFS(BASE_FIXA_TEND!AN:AN,BASE_FIXA_TEND!$A:$A,$A10,BASE_FIXA_TEND!$B:$B,$E10,BASE_FIXA_TEND!$D:$D,$F10) -> 0
A11: RBS | B11: 46054 | C11: =TEXT(B11,"MM") -> 02 | D11: =YEAR(B11) -> 2026 | E11: Hospitality PME | F11: Instalação | G11: FIXA | H11: 0 | I11: 0 | J11: =B11 -> 46054 | K11: =TEXT(J11,"MMM/AA") -> fev/26 | L11: =TEXT(J11,"DDD") -> dom | M11: =SUMIFS(BASE_FIXA_TEND!AN:AN,BASE_FIXA_TEND!$A:$A,$A11,BASE_FIXA_TEND!$B:$B,$E11,BASE_FIXA_TEND!$D:$D,$F11) -> 0
A12: RSI | B12: 46054 | C12: =TEXT(B12,"MM") -> 02 | D12: =YEAR(B12) -> 2026 | E12: Hospitality PME | F12: Venda Bruta | G12: FIXA | H12: 0 | I12: 0 | J12: =B12 -> 46054 | K12: =TEXT(J12,"MMM/AA") -> fev/26 | L12: =TEXT(J12,"DDD") -> dom | M12: =SUMIFS(BASE_FIXA_TEND!AN:AN,BASE_FIXA_TEND!$A:$A,$A12,BASE_FIXA_TEND!$B:$B,$E12,BASE_FIXA_TEND!$D:$D,$F12) -> 5
A13: RRE | B13: 46054 | C13: =TEXT(B13,"MM") -> 02 | D13: =YEAR(B13) -> 2026 | E13: Hospitality PME | F13: Venda Bruta | G13: FIXA | H13: 0 | I13: 0 | J13: =B13 -> 46054 | K13: =TEXT(J13,"MMM/AA") -> fev/26 | L13: =TEXT(J13,"DDD") -> dom | M13: =SUMIFS(BASE_FIXA_TEND!AN:AN,BASE_FIXA_TEND!$A:$A,$A13,BASE_FIXA_TEND!$B:$B,$E13,BASE_FIXA_TEND!$D:$D,$F13) -> 0
... A141: RBS | B141: 46054 | C141: =TEXT(B141,"MM") -> 02 | D141: =YEAR(B141) -> 2026 | E141: S2S | F141: Venda Bruta | G141: FIXA | H141: 0 | I141: 0 | J141: =B141 -> 46054 | K141: =TEXT(J141,"MMM/AA") -> fev/26 | L141: =TEXT(J141,"DDD") -> dom | M141: =SUMIFS(BASE_FIXA_TEND!AN:AN,BASE_FIXA_TEND!$A:$A,$A141,BASE_FIXA_TEND!$B:$B,$E141,BASE_FIXA_TEND!$D:$D,$F141) -> 2
A142: RSI | B142: 46054 | C142: =TEXT(B142,"MM") -> 02 | D142: =YEAR(B142) -> 2026 | E142: E-Commerce | F142: GROSS BRUTO | G142: CONTA | H142: 0 | I142: 0 | J142: =B142 -> 46054 | K142: =TEXT(J142,"MMM/AA") -> fev/26 | L142: =TEXT(J142,"DDD") -> dom | M142: =SUMIFS(BASE_MOVEL_TEND!$D:$D,BASE_MOVEL_TEND!$A:$A,$F142,BASE_MOVEL_TEND!$B:$B,$E142,BASE_MOVEL_TEND!$C:$C,$A142) -> 393.56057
A143: RRE | B143: 46054 | C143: =TEXT(B143,"MM") -> 02 | D143: =YEAR(B143) -> 2026 | E143: E-Commerce | F143: GROSS BRUTO | G143: CONTA | H143: 0 | I143: 0 | J143: =B143 -> 46054 | K143: =TEXT(J143,"MMM/AA") -> fev/26 | L143: =TEXT(J143,"DDD") -> dom | M143: =SUMIFS(BASE_MOVEL_TEND!$D:$D,BASE_MOVEL_TEND!$A:$A,$F143,BASE_MOVEL_TEND!$B:$B,$E143,BASE_MOVEL_TEND!$C:$C,$A143) -> 465.04541
A144: RMG | B144: 46054 | C144: =TEXT(B144,"MM") -> 02 | D144: =YEAR(B144) -> 2026 | E144: E-Commerce | F144: GROSS BRUTO | G144: CONTA | H144: 0 | I144: 0 | J144: =B144 -> 46054 | K144: =TEXT(J144,"MMM/AA") -> fev/26 | L144: =TEXT(J144,"DDD") -> dom | M144: =SUMIFS(BASE_MOVEL_TEND!$D:$D,BASE_MOVEL_TEND!$A:$A,$F144,BASE_MOVEL_TEND!$B:$B,$E144,BASE_MOVEL_TEND!$C:$C,$A144) -> 202.79922
A145: RPS | B145: 46054 | C145: =TEXT(B145,"MM") -> 02 | D145: =YEAR(B145) -> 2026 | E145: E-Commerce | F145: GROSS BRUTO | G145: CONTA | H145: 0 | I145: 0 | J145: =B145 -> 46054 | K145: =TEXT(J145,"MMM/AA") -> fev/26 | L145: =TEXT(J145,"DDD") -> dom | M145: =SUMIFS(BASE_MOVEL_TEND!$D:$D,BASE_MOVEL_TEND!$A:$A,$F145,BASE_MOVEL_TEND!$B:$B,$E145,BASE_MOVEL_TEND!$C:$C,$A145) -> 400.04846
A146: RRS | B146: 46054 | C146: =TEXT(B146,"MM") -> 02 | D146: =YEAR(B146) -> 2026 | E146: E-Commerce | F146: GROSS BRUTO | G146: CONTA | H146: 0 | I146: 0 | J146: =B146 -> 46054 | K146: =TEXT(J146,"MMM/AA") -> fev/26 | L146: =TEXT(J146,"DDD") -> dom | M146: =SUMIFS(BASE_MOVEL_TEND!$D:$D,BASE_MOVEL_TEND!$A:$A,$F146,BASE_MOVEL_TEND!$B:$B,$E146,BASE_MOVEL_TEND!$C:$C,$A146) -> 176.65907
A147: RCO | B147: 46054 | C147: =TEXT(B147,"MM") -> 02 | D147: =YEAR(B147) -> 2026 | E147: E-Commerce | F147: GROSS BRUTO | G147: CONTA | H147: 0 | I147: 0 | J147: =B147 -> 46054 | K147: =TEXT(J147,"MMM/AA") -> fev/26 | L147: =TEXT(J147,"DDD") -> dom | M147: =SUMIFS(BASE_MOVEL_TEND!$D:$D,BASE_MOVEL_TEND!$A:$A,$F147,BASE_MOVEL_TEND!$B:$B,$E147,BASE_MOVEL_TEND!$C:$C,$A147) -> 434.18178
A148: RNE | B148: 46054 | C148: =TEXT(B148,"MM") -> 02 | D148: =YEAR(B148) -> 2026 | E148: E-Commerce | F148: GROSS BRUTO | G148: CONTA | H148: 0 | I148: 0 | J148: =B148 -> 46054 | K148: =TEXT(J148,"MMM/AA") -> fev/26 | L148: =TEXT(J148,"DDD") -> dom | M148: =SUMIFS(BASE_MOVEL_TEND!$D:$D,BASE_MOVEL_TEND!$A:$A,$F148,BASE_MOVEL_TEND!$B:$B,$E148,BASE_MOVEL_TEND!$C:$C,$A148) -> 262.11664
A149: RSC | B149: 46054 | C149: =TEXT(B149,"MM") -> 02 | D149: =YEAR(B149) -> 2026 | E149: E-Commerce | F149: GROSS BRUTO | G149: CONTA | H149: 0 | I149: 0 | J149: =B149 -> 46054 | K149: =TEXT(J149,"MMM/AA") -> fev/26 | L149: =TEXT(J149,"DDD") -> dom | M149: =SUMIFS(BASE_MOVEL_TEND!$D:$D,BASE_MOVEL_TEND!$A:$A,$F149,BASE_MOVEL_TEND!$B:$B,$E149,BASE_MOVEL_TEND!$C:$C,$A149) -> 983.5037
A150: RNO | B150: 46054 | C150: =TEXT(B150,"MM") -> 02 | D150: =YEAR(B150) -> 2026 | E150: E-Commerce | F150: GROSS BRUTO | G150: CONTA | H150: 0 | I150: 0 | J150: =B150 -> 46054 | K150: =TEXT(J150,"MMM/AA") -> fev/26 | L150: =TEXT(J150,"DDD") -> dom | M150: =SUMIFS(BASE_MOVEL_TEND!$D:$D,BASE_MOVEL_TEND!$A:$A,$F150,BASE_MOVEL_TEND!$B:$B,$E150,BASE_MOVEL_TEND!$C:$C,$A150) -> 123.09241
A151: RBS | B151: 46054 | C151: =TEXT(B151,"MM") -> 02 | D151: =YEAR(B151) -> 2026 | E151: E-Commerce | F151: GROSS BRUTO | G151: CONTA | H151: 0 | I151: 0 | J151: =B151 -> 46054 | K151: =TEXT(J151,"MMM/AA") -> fev/26 | L151: =TEXT(J151,"DDD") -> dom | M151: =SUMIFS(BASE_MOVEL_TEND!$D:$D,BASE_MOVEL_TEND!$A:$A,$F151,BASE_MOVEL_TEND!$B:$B,$E151,BASE_MOVEL_TEND!$C:$C,$A151) -> 138.38256
A152: RSI | B152: 46054 | C152: =TEXT(B152,"MM") -> 02 | D152: =YEAR(B152) -> 2026 | E152: E-Commerce | F152: GROSS LIQUIDO | G152: CONTA | H152: 0 | I152: 0 | J152: =B152 -> 46054 | K152: =TEXT(J152,"MMM/AA") -> fev/26 | L152: =TEXT(J152,"DDD") -> dom | M152: =SUMIFS(BASE_MOVEL_TEND!$D:$D,BASE_MOVEL_TEND!$A:$A,$F152,BASE_MOVEL_TEND!$B:$B,$E152,BASE_MOVEL_TEND!$C:$C,$A152) -> 367.31815
A153: RRE | B153: 46054 | C153: =TEXT(B153,"MM") -> 02 | D153: =YEAR(B153) -> 2026 | E153: E-Commerce | F153: GROSS LIQUIDO | G153: CONTA | H153: 0 | I153: 0 | J153: =B153 -> 46054 | K153: =TEXT(J153,"MMM/AA") -> fev/26 | L153: =TEXT(J153,"DDD") -> dom | M153: =SUMIFS(BASE_MOVEL_TEND!$D:$D,BASE_MOVEL_TEND!$A:$A,$F153,BASE_MOVEL_TEND!$B:$B,$E153,BASE_MOVEL_TEND!$C:$C,$A153) -> 414.47193
... A261: RBS | B261: 46054 | C261: =TEXT(B261,"MM") -> 02 | D261: =YEAR(B261) -> 2026 | E261: S2S | F261: GROSS LIQUIDO | G261: CONTA | H261: 0 | I261: 0 | J261: =B261 -> 46054 | K261: =TEXT(J261,"MMM/AA") -> fev/26 | L261: =TEXT(J261,"DDD") -> dom | M261: =SUMIFS(BASE_MOVEL_TEND!$D:$D,BASE_MOVEL_TEND!$A:$A,$F261,BASE_MOVEL_TEND!$B:$B,$E261,BASE_MOVEL_TEND!$C:$C,$A261) -> 12.965907
A262: RSI | B262: 46054 | C262: =TEXT(B262,"MM") -> 02 | D262: =YEAR(B262) -> 2026 | E262: E-Commerce | F262: PEDIDOS | G262: CONTA | H262: 0 | I262: 0 | J262: =B262 -> 46054 | K262: =TEXT(J262,"MMM/AA") -> fev/26 | L262: =TEXT(J262,"DDD") -> dom | M262: =SUMIFS(PEDIDOS_MÓVEL!$D:$D,PEDIDOS_MÓVEL!$A:$A,A262) -> 824.75942
A263: RRE | B263: 46054 | C263: =TEXT(B263,"MM") -> 02 | D263: =YEAR(B263) -> 2026 | E263: E-Commerce | F263: PEDIDOS | G263: CONTA | H263: 0 | I263: 0 | J263: =B263 -> 46054 | K263: =TEXT(J263,"MMM/AA") -> fev/26 | L263: =TEXT(J263,"DDD") -> dom | M263: =SUMIFS(PEDIDOS_MÓVEL!$D:$D,PEDIDOS_MÓVEL!$A:$A,A263) -> 1068.2854
A264: RMG | B264: 46054 | C264: =TEXT(B264,"MM") -> 02 | D264: =YEAR(B264) -> 2026 | E264: E-Commerce | F264: PEDIDOS | G264: CONTA | H264: 0 | I264: 0 | J264: =B264 -> 46054 | K264: =TEXT(J264,"MMM/AA") -> fev/26 | L264: =TEXT(J264,"DDD") -> dom | M264: =SUMIFS(PEDIDOS_MÓVEL!$D:$D,PEDIDOS_MÓVEL!$A:$A,A264) -> 414.39788
A265: RPS | B265: 46054 | C265: =TEXT(B265,"MM") -> 02 | D265: =YEAR(B265) -> 2026 | E265: E-Commerce | F265: PEDIDOS | G265: CONTA | H265: 0 | I265: 0 | J265: =B265 -> 46054 | K265: =TEXT(J265,"MMM/AA") -> fev/26 | L265: =TEXT(J265,"DDD") -> dom | M265: =SUMIFS(PEDIDOS_MÓVEL!$D:$D,PEDIDOS_MÓVEL!$A:$A,A265) -> 765.55972
A266: RRS | B266: 46054 | C266: =TEXT(B266,"MM") -> 02 | D266: =YEAR(B266) -> 2026 | E266: E-Commerce | F266: PEDIDOS | G266: CONTA | H266: 0 | I266: 0 | J266: =B266 -> 46054 | K266: =TEXT(J266,"MMM/AA") -> fev/26 | L266: =TEXT(J266,"DDD") -> dom | M266: =SUMIFS(PEDIDOS_MÓVEL!$D:$D,PEDIDOS_MÓVEL!$A:$A,A266) -> 372.689
A267: RCO | B267: 46054 | C267: =TEXT(B267,"MM") -> 02 | D267: =YEAR(B267) -> 2026 | E267: E-Commerce | F267: PEDIDOS | G267: CONTA | H267: 0 | I267: 0 | J267: =B267 -> 46054 | K267: =TEXT(J267,"MMM/AA") -> fev/26 | L267: =TEXT(J267,"DDD") -> dom | M267: =SUMIFS(PEDIDOS_MÓVEL!$D:$D,PEDIDOS_MÓVEL!$A:$A,A267) -> 757.48703
A268: RNE | B268: 46054 | C268: =TEXT(B268,"MM") -> 02 | D268: =YEAR(B268) -> 2026 | E268: E-Commerce | F268: PEDIDOS | G268: CONTA | H268: 0 | I268: 0 | J268: =B268 -> 46054 | K268: =TEXT(J268,"MMM/AA") -> fev/26 | L268: =TEXT(J268,"DDD") -> dom | M268: =SUMIFS(PEDIDOS_MÓVEL!$D:$D,PEDIDOS_MÓVEL!$A:$A,A268) -> 597.37876
A269: RSC | B269: 46054 | C269: =TEXT(B269,"MM") -> 02 | D269: =YEAR(B269) -> 2026 | E269: E-Commerce | F269: PEDIDOS | G269: CONTA | H269: 0 | I269: 0 | J269: =B269 -> 46054 | K269: =TEXT(J269,"MMM/AA") -> fev/26 | L269: =TEXT(J269,"DDD") -> dom | M269: =SUMIFS(PEDIDOS_MÓVEL!$D:$D,PEDIDOS_MÓVEL!$A:$A,A269) -> 1781.3727
A270: RNO | B270: 46054 | C270: =TEXT(B270,"MM") -> 02 | D270: =YEAR(B270) -> 2026 | E270: E-Commerce | F270: PEDIDOS | G270: CONTA | H270: 0 | I270: 0 | J270: =B270 -> 46054 | K270: =TEXT(J270,"MMM/AA") -> fev/26 | L270: =TEXT(J270,"DDD") -> dom | M270: =SUMIFS(PEDIDOS_MÓVEL!$D:$D,PEDIDOS_MÓVEL!$A:$A,A270) -> 295.99849
A271: RBS | B271: 46054 | C271: =TEXT(B271,"MM") -> 02 | D271: =YEAR(B271) -> 2026 | E271: E-Commerce | F271: PEDIDOS | G271: CONTA | H271: 0 | I271: 0 | J271: =B271 -> 46054 | K271: =TEXT(J271,"MMM/AA") -> fev/26 | L271: =TEXT(J271,"DDD") -> dom | M271: =SUMIFS(PEDIDOS_MÓVEL!$D:$D,PEDIDOS_MÓVEL!$A:$A,A271) -> 230.07155
A272: RSI | B272: 46054 | C272: =TEXT(B272,"MM") -> 02 | D272: =YEAR(B272) -> 2026 | E272: E-Commerce | F272: PEDIDOS | G272: FIXA | H272: 0 | I272: 0 | J272: =B272 -> 46054 | K272: =TEXT(J272,"MMM/AA") -> fev/26 | L272: =TEXT(J272,"DDD") -> dom | M272: =SUMIFS(PEDIDOS_FIXA!B:B,PEDIDOS_FIXA!A:A,A272) -> 866.13705
A273: RRE | B273: 46054 | C273: =TEXT(B273,"MM") -> 02 | D273: =YEAR(B273) -> 2026 | E273: E-Commerce | F273: PEDIDOS | G273: FIXA | H273: 0 | I273: 0 | J273: =B273 -> 46054 | K273: =TEXT(J273,"MMM/AA") -> fev/26 | L273: =TEXT(J273,"DDD") -> dom | M273: =SUMIFS(PEDIDOS_FIXA!B:B,PEDIDOS_FIXA!A:A,A273) -> 872.23625
A274: RMG | B274: 46054 | C274: =TEXT(B274,"MM") -> 02 | D274: =YEAR(B274) -> 2026 | E274: E-Commerce | F274: PEDIDOS | G274: FIXA | H274: 0 | I274: 0 | J274: =B274 -> 46054 | K274: =TEXT(J274,"MMM/AA") -> fev/26 | L274: =TEXT(J274,"DDD") -> dom | M274: =SUMIFS(PEDIDOS_FIXA!B:B,PEDIDOS_FIXA!A:A,A274) -> 446.15637
...

Sheet LIGACOE_FIXA
A2: RSC | B2: 2330.0175
A3: RSI | B3: 1050.7528
A4: RBS | B4: 1396.0909
A5: RCO | B5: 613.29201
A6: RMG | B6: 702.07969
A7: RNE | B7: 334.45642
A8: RNO | B8: 728.75269
A9: RPS | B9: 251.38719
A10: RRE | B10: 426.58066
A11: RRS | B11: 229.59009

Sheet PEDIDOS_FIXA
A2: RSC | B2: 1729.8158
A3: RSI | B3: 866.13705
A4: RRE | B4: 872.23625
A5: RMG | B5: 446.15637
A6: RPS | B6: 691.3785
A7: RRS | B7: 284.83739
A8: RCO | B8: 463.33845
A9: RBS | B9: 156.22867
A10: RNE | B10: 223.95383
A11: RNO | B11: 236.91774

Sheet PEDIDOS_MÓVEL
B1: TEND | D1: TOTAL REAL | E1: 6967
A2: PEDIDOS - REGIONAL | B2: 5540.2454 | D2: TEND_REAL
A3: RSC | B3: 1773.7764 | C3: =B3/$B$2 -> 0.32016206 | D3: 1781.3727 | E3: CONTA
A4: RSI | B4: 792.11803 | C4: =B4/$B$2 -> 0.14297526 | D4: 824.75942 | E4: CONTA
A5: RRE | B5: 1049.3561 | C5: =B5/$B$2 -> 0.18940606 | D5: 1068.2854 | E5: CONTA
A6: RMG | B6: 400.85093 | C6: =B6/$B$2 -> 0.072352558 | D6: 414.39788 | E6: CONTA
A7: RPS | B7: 766.74725 | C7: =B7/$B$2 -> 0.1383959 | D7: 765.55972 | E7: CONTA
A8: RRS | B8: 343.6753 | C8: =B8/$B$2 -> 0.062032505 | D8: 372.689 | E8: CONTA
A9: RCO | B9: 746.67499 | C9: =B9/$B$2 -> 0.13477291 | D9: 757.48703 | E9: CONTA
A10: RBS | B10: 222.33062 | C10: =B10/$B$2 -> 0.040130103 | D10: 230.07155 | E10: CONTA
A11: RNE | B11: 571.00838 | C11: =B11/$B$2 -> 0.10306554 | D11: 597.37876 | E11: CONTA
A12: RNO | B12: 300.46202 | C12: =B12/$B$2 -> 0.054232619 | D12: 295.99849 | E12: CONTA

Sheet BASE_FIXA_TEND
A1: REGIONAL | B1: NM_CANAL_AJUSTADO | C1: NM_MERCADO | D1: INDICADOR DE NEGÓCIO | E1: NR_ANO_MES | F1: NM_PARCEIRO | G1: 1 | H1: 2 | I1: 3 | J1: 4 | K1: 5 | L1: 6 | M1: 7 | N1: 8 | O1: 9 | P1: 10 | Q1: 11 | R1: 12 | S1: 13 | T1: 14 | U1: 15 | V1: 16 | W1: 17 | X1: 18 | Y1: 19 | Z1: 20 | AA1: 21 | AB1: 22 | AC1: 23 | AD1: 24 | AE1: 25 | AF1: 26 | AG1: 27 | AH1: 28 | AI1: 29 | AJ1: 30 | AK1: 31 | AL1: MÊS | AM1: 20.666667 | AN1: TEND.
A2: RSI | B2: Porta Porta Premium | C2: Pessoa Jurídica | D2: Instalação | E2: 202602 | F2: CLARO S.A. 4016906 | G2: 0 | H2: 4 | I2: 0 | J2: 0 | K2: 1 | L2: 1 | M2: 2 | N2: 0 | O2: 0 | P2: 0 | Q2: 2 | R2: 2 | S2: 0 | T2: 2 | U2: 0 | V2: 0 | W2: 0 | X2: 1 | Y2: 0 | Z2: 0 | AA2: 0 | AB2: 1 | AC2: 1 | AD2: 0 | AE2: 0 | AF2: 0 | AG2: 0 | AH2: 0 | AI2: 0 | AJ2: 0 | AK2: 0 | AL2: 17 | AM2: 0.33333333 | AN2: 18.679669
A3: RSI | B3: Porta Porta Premium | C3: Pessoa Jurídica | D3: Instalação | E3: 202602 | F3: CLARO SA 4055200 | G3: 0 | H3: 1 | I3: 0 | J3: 1 | K3: 4 | L3: 1 | M3: 1 | N3: 0 | O3: 1 | P3: 1 | Q3: 0 | R3: 1 | S3: 2 | T3: 0 | U3: 0 | V3: 1 | W3: 0 | X3: 1 | Y3: 1 | Z3: 0 | AA3: 0 | AB3: 0 | AC3: 3 | AD3: 0 | AE3: 0 | AF3: 0 | AG3: 0 | AH3: 0 | AI3: 0 | AJ3: 0 | AK3: 0 | AL3: 19 | AM3: 1.3333333 | AN3: 25.718674
A4: RSI | B4: Porta Porta Premium | C4: Pessoa Jurídica | D4: Instalação | E4: 202602 | F4: CLARO SA 4074183 | G4: 0 | H4: 0 | I4: 0 | J4: 0 | K4: 0 | L4: 0 | M4: 0 | N4: 0 | O4: 0 | P4: 0 | Q4: 0 | R4: 1 | S4: 0 | T4: 0 | U4: 0 | V4: 0 | W4: 0 | X4: 0 | Y4: 0 | Z4: 0 | AA4: 0 | AB4: 0 | AC4: 0 | AD4: 0 | AE4: 0 | AF4: 0 | AG4: 0 | AH4: 0 | AI4: 0 | AJ4: 0 | AK4: 0 | AL4: 1 | AM4: 0 | AN4: 1
A5: RSI | B5: Porta Porta Premium | C5: Pessoa Jurídica | D5: Instalação | E5: 202602 | F5: CLARO SA 4094370 | G5: 0 | H5: 0 | I5: 0 | J5: 0 | K5: 0 | L5: 0 | M5: 0 | N5: 0 | O5: 0 | P5: 0 | Q5: 0 | R5: 1 | S5: 0 | T5: 0 | U5: 0 | V5: 0 | W5: 0 | X5: 0 | Y5: 0 | Z5: 0 | AA5: 0 | AB5: 0 | AC5: 0 | AD5: 0 | AE5: 0 | AF5: 0 | AG5: 0 | AH5: 0 | AI5: 0 | AJ5: 0 | AK5: 0 | AL5: 1 | AM5: 0 | AN5: 1
A6: RSI | B6: Porta Porta Premium | C6: Pessoa Jurídica | D6: Venda Bruta | E6: 202602 | F6: CLARO S.A. 4016906 | G6: 0 | H6: 3 | I6: 2 | J6: 0 | K6: 1 | L6: 1 | M6: 0 | N6: 0 | O6: 1 | P6: 1 | Q6: 2 | R6: 1 | S6: 2 | T6: 0 | U6: 0 | V6: 0 | W6: 0 | X6: 0 | Y6: 1 | Z6: 2 | AA6: 0 | AB6: 0 | AC6: 3 | AD6: 0 | AE6: 0 | AF6: 0 | AG6: 0 | AH6: 0 | AI6: 0 | AJ6: 0 | AK6: 0 | AL6: 20 | AM6: 2 | AN6: 28.605449
A7: RSI | B7: Porta Porta Premium | C7: Pessoa Jurídica | D7: Venda Bruta | E7: 202602 | F7: CLARO SA 4055200 | G7: 0 | H7: 3 | I7: 1 | J7: 2 | K7: 0 | L7: 1 | M7: 0 | N7: 1 | O7: 0 | P7: 1 | Q7: 2 | R7: 1 | S7: 3 | T7: 0 | U7: 0 | V7: 1 | W7: 0 | X7: 3 | Y7: 2 | Z7: 0 | AA7: 1 | AB7: 0 | AC7: 2 | AD7: 0 | AE7: 0 | AF7: 0 | AG7: 0 | AH7: 0 | AI7: 0 | AJ7: 0 | AK7: 0 | AL7: 24 | AM7: 1.3333333 | AN7: 29.736966
A8: RSI | B8: Porta Porta Premium | C8: Pessoa Jurídica | D8: Venda Bruta | E8: 202602 | F8: CLARO S.A. 75155 | G8: 0 | H8: 0 | I8: 0 | J8: 0 | K8: 0 | L8: 0 | M8: 0 | N8: 0 | O8: 0 | P8: 0 | Q8: 0 | R8: 0 | S8: 1 | T8: 0 | U8: 0 | V8: 0 | W8: 0 | X8: 1 | Y8: 0 | Z8: 0 | AA8: 0 | AB8: 0 | AC8: 0 | AD8: 0 | AE8: 0 | AF8: 0 | AG8: 0 | AH8: 0 | AI8: 0 | AJ8: 0 | AK8: 0 | AL8: 2 | AM8: 0 | AN8: 2
A9: RSI | B9: Porta Porta Premium | C9: Pessoa Jurídica | D9: Venda Bruta | E9: 202602 | F9: CLARO SA 4074183 | G9: 0 | H9: 0 | I9: 0 | J9: 0 | K9: 0 | L9: 0 | M9: 0 | N9: 0 | O9: 0 | P9: 0 | Q9: 1 | R9: 0 | S9: 0 | T9: 0 | U9: 0 | V9: 0 | W9: 0 | X9: 0 | Y9: 0 | Z9: 0 | AA9: 0 | AB9: 0 | AC9: 0 | AD9: 0 | AE9: 0 | AF9: 0 | AG9: 0 | AH9: 0 | AI9: 0 | AJ9: 0 | AK9: 0 | AL9: 1 | AM9: 0 | AN9: 1
A10: RSI | B10: Porta Porta Premium | C10: Pessoa Jurídica | D10: Venda Bruta | E10: 202602 | F10: CLARO SA 4094370 | G10: 0 | H10: 0 | I10: 0 | J10: 0 | K10: 0 | L10: 0 | M10: 0 | N10: 0 | O10: 1 | P10: 0 | Q10: 0 | R10: 0 | S10: 0 | T10: 0 | U10: 0 | V10: 0 | W10: 0 | X10: 0 | Y10: 0 | Z10: 0 | AA10: 0 | AB10: 0 | AC10: 0 | AD10: 0 | AE10: 0 | AF10: 0 | AG10: 0 | AH10: 0 | AI10: 0 | AJ10: 0 | AK10: 0 | AL10: 1 | AM10: 0 | AN10: 1
A11: RSI | B11: Porta Porta Premium | C11: Pessoa Física | D11: Instalação | E11: 202602 | F11: CLARO S.A. 4016906 | G11: 0 | H11: 0 | I11: 0 | J11: 0 | K11: 0 | L11: 0 | M11: 0 | N11: 0 | O11: 0 | P11: 0 | Q11: 1 | R11: 0 | S11: 1 | T11: 0 | U11: 0 | V11: 0 | W11: 0 | X11: 1 | Y11: 0 | Z11: 0 | AA11: 0 | AB11: 0 | AC11: 0 | AD11: 0 | AE11: 0 | AF11: 0 | AG11: 0 | AH11: 0 | AI11: 0 | AJ11: 0 | AK11: 0 | AL11: 3 | AM11: 0 | AN11: 3
A12: RSI | B12: Porta Porta Premium | C12: Pessoa Física | D12: Instalação | E12: 202602 | F12: CLARO SA 4055200 | G12: 0 | H12: 0 | I12: 0 | J12: 0 | K12: 1 | L12: 0 | M12: 0 | N12: 0 | O12: 0 | P12: 0 | Q12: 0 | R12: 0 | S12: 0 | T12: 0 | U12: 0 | V12: 0 | W12: 0 | X12: 0 | Y12: 0 | Z12: 0 | AA12: 0 | AB12: 0 | AC12: 0 | AD12: 0 | AE12: 0 | AF12: 0 | AG12: 0 | AH12: 0 | AI12: 0 | AJ12: 0 | AK12: 0 | AL12: 1 | AM12: 0 | AN12: 1
A13: RSI | B13: Porta Porta Premium | C13: Pessoa Física | D13: Instalação | E13: 202602 | F13: CLARO SA 4078170 | G13: 0 | H13: 0 | I13: 0 | J13: 0 | K13: 0 | L13: 0 | M13: 0 | N13: 0 | O13: 0 | P13: 0 | Q13: 0 | R13: 0 | S13: 0 | T13: 0 | U13: 0 | V13: 0 | W13: 0 | X13: 0 | Y13: 0 | Z13: 0 | AA13: 1 | AB13: 0 | AC13: 0 | AD13: 0 | AE13: 0 | AF13: 0 | AG13: 0 | AH13: 0 | AI13: 0 | AJ13: 0 | AK13: 0 | AL13: 1 | AM13: 0 | AN13: 1
... A2949: RBS | B2949: S2S | C2949: Pessoa Jurídica | D2949: Venda Bruta | E2949: 202602 | F2949: TEL CENTRO DE CONTATOS LTDA | G2949: 0 | H2949: 0 | I2949: 0 | J2949: 1 | K2949: 0 | L2949: 1 | M2949: 0 | N2949: 0 | O2949: 0 | P2949: 0 | Q2949: 0 | R2949: 0 | S2949: 0 | T2949: 0 | U2949: 0 | V2949: 0 | W2949: 0 | X2949: 0 | Y2949: 0 | Z2949: 0 | AA2949: 0 | AB2949: 0 | AC2949: 0 | AD2949: 0 | AE2949: 0 | AF2949: 0 | AG2949: 0 | AH2949: 0 | AI2949: 0 | AJ2949: 0 | AK2949: 0 | AL2949: 2 | AM2949: 0 | AN2949: 2
AL2950: 0
AL2951: 0
AL2952: 0
AL2953: 0
AL2954: 0
AL2955: 0
AL2956: 0
AL2957: 0
AL2958: 0
AL2959: 0
AL2960: 0
AL2961: 0
... AL5767: 0

Sheet BASE_MOVEL_TEND
A1: INDICADOR | B1: CANAL | C1: REGIONAL | D1: CONTA
A2: GROSS BRUTO | B2: Agente Autorizado Claro Empresas | C2: RSC | D2: 4032.5578
A3: GROSS BRUTO | B3: Agente Autorizado Claro Empresas | C3: RSI | D3: 1655.3013
A4: GROSS BRUTO | B4: Agente Autorizado Claro Empresas | C4: RRE | D4: 1186.9801
A5: GROSS BRUTO | B5: Agente Autorizado Claro Empresas | C5: RMG | D5: 999.81953
A6: GROSS BRUTO | B6: Agente Autorizado Claro Empresas | C6: RPS | D6: 2895.5822
A7: GROSS BRUTO | B7: Agente Autorizado Claro Empresas | C7: RRS | D7: 2005.9421
A8: GROSS BRUTO | B8: Agente Autorizado Claro Empresas | C8: RCO | D8: 2310.0284
A9: GROSS BRUTO | B9: Agente Autorizado Claro Empresas | C9: RBS | D9: 399.70144
A10: GROSS BRUTO | B10: Agente Autorizado Claro Empresas | C10: RNE | D10: 2262.3435
A11: GROSS BRUTO | B11: Agente Autorizado Claro Empresas | C11: RNO | D11: 982.05673
A12: GROSS BRUTO | B12: Top PME | C12: RSC | D12: 1514.2907
A13: GROSS BRUTO | B13: Top PME | C13: RSI | D13: 709.10141
... A26: GROSS BRUTO | B26: Porta Porta PME | C26: RPS | D26: 1.6553025
A27: GROSS BRUTO | B27: Porta Porta PME | C27: RRS
A28: GROSS BRUTO | B28: Porta Porta PME | C28: RCO | D28: 4
A29: GROSS BRUTO | B29: Porta Porta PME | C29: RBS
A30: GROSS BRUTO | B30: Porta Porta PME | C30: RNE | D30: 40.566662
A31: GROSS BRUTO | B31: Porta Porta PME | C31: RNO
A32: GROSS BRUTO | B32: Porta Porta PME | C32: RSC | D32: 3.3174235
A33: GROSS BRUTO | B33: Porta Porta PME | C33: RSI | D33: 8.6416655
A34: GROSS BRUTO | B34: Porta Porta PME | C34: RRE | D34: 0.9931815
A35: GROSS BRUTO | B35: Porta Porta PME | C35: RMG | D35: 2.9795445
A36: GROSS BRUTO | B36: Porta Porta PME | C36: RPS
A37: GROSS BRUTO | B37: Porta Porta PME | C37: RRS | D37: 0.662121
A38: GROSS BRUTO | B38: Porta Porta PME | C38: RCO | D38: 3.310605
A39: GROSS BRUTO | B39: Porta Porta PME | C39: RBS | D39: 0
A40: GROSS BRUTO | B40: Porta Porta PME | C40: RNE
A41: GROSS BRUTO | B41: Porta Porta PME | C41: RNO | D41: 0.3310605
A42: GROSS BRUTO | B42: LA/ MA | C42: RSC | D42: 270.80749
A43: GROSS BRUTO | B43: LA/ MA | C43: RSI
A44: GROSS BRUTO | B44: LA/ MA | C44: RRE
A45: GROSS BRUTO | B45: LA/ MA | C45: RMG
A46: GROSS BRUTO | B46: LA/ MA | C46: RPS
A47: GROSS BRUTO | B47: LA/ MA | C47: RRS
A48: GROSS BRUTO | B48: LA/ MA | C48: RCO
A49: GROSS BRUTO | B49: LA/ MA | C49: RBS
A50: GROSS BRUTO | B50: LA/ MA | C50: RNE | D50: 0.3310605
A51: GROSS BRUTO | B51: LA/ MA | C51: RNO
A52: GROSS BRUTO | B52: Grandes Marcas PME | C52: RSC
...

Sheet obs
A1: Lembrar de ajustar o nome dos canais na base
